Workbook

Sheet About us 
B11: Team Members | C11: Owner's Id
B12: Aditi Agrawal | C12: DM253005
B13: Ayush Gautam | C13: DM251023
B14: Manshi Chandak | C14: DM254036
B15: Mayank Khandelwal | C15: DM252040
B16: N. Pravena | C16: DM253047
B17: Subhrajyoti Sen Chaudhuri | C17: DM254074
B18: V V Chanikya | C18: DM251084
B19: Yash Agarwal | C19: DM253085

Sheet Index
B2: Sl no | C2: Sheet
B3: 1 | C3: Assumption
B4: 2 | C4: Schedules
B5: 3 | C5: Income Statement'
B6: 4 | C6: Balance Sheet'
B7: 5 | C7: Cash Flow Statement'
B8: 6 | C8: Output Analysis-NPV_IRR'
B9: 7 | C9: References

Sheet Assumption
B1: All amounts in Rupees otherwise stated
B2: All inputs in colour RED
B3: All projections in BLUE
B5: We have been in operations for a year
B6: Projections start from 2nd year (2025)
B8: Project Duration
B9: Project Start Date | C9: 45017
C10: 0
B11: Forecast End | C11: =EDATE(C9,C10) -> 45017
B13: Cost of Goods Sold | C13: per ut
B14: Material Cost | C14: 0.5
B15: Manufacturing cost | C15: 0.25
B16: R&D | C16: 0.02
B17: Transportation and Logistics | C17: 0.23
C18: =SUM(C14:C17)=1 -> TRUE
B20: Operating Expenses | C20: as a % of Sales
B21: Sales and Marketing | C21: 0.06
B22: Employee Cost | C22: 0.02
B23: Other Expenses | C23: 0.35
B24: *Sales & Marketing Cost includes Advertising, promotions and sales staff costs
B26: Tax & Inflation
B27: Income Tax Rate | C27: 0.25
B28: Tax holiday | C28: 2
B29: Inflation for Commercial | C29: 0.05
B30: Inflation for Residential | C30: 0.025
B32: Capex | C32: Value | D32: Dep(%) | E32: Scrap(%) | H32: Capex Schedule | I32: Year1 | J32: Year2 | K32: Year3 | L32: Year4 | M32: Year5 | N32: Year 6
B33: Land | C33: 50000000 | D33: 0 | E33: 0 | I33: 1 | J33: 0 | K33: 0 | L33: 0 | M33: 0 | N33: 0 | O33: =SUM(I33:N33)=1 -> TRUE
B34: Building | C34: 20000000 | D34: 0.02 | E34: 0.3 | I34: 0.35 | J34: 0.2 | K34: 0.15 | L34: 0.1 | M34: 0.1 | N34: 0.1 | O34: =SUM(I34:N34)=1 -> TRUE
B35: Machinery | C35: 100000000 | D35: 0.0666 | E35: 0.2 | I35: 0.4 | J35: 0.3 | K35: 0.2 | L35: 0.1 | M35: 0 | N35: 0 | O35: =SUM(I35:N35)=1 -> TRUE
B38: Capital Structure | E38: Debt Structure
B39: Equity | C39: 0.8 | E39: Debt Period in yrs | F39: 10
B40: Debt | C40: 0.05 | E40: Moratorium Period | F40: 0
B41: Grants | C41: 0.15 | E41: LT Interest Rates | F41: 0.065
C42: =SUM(C39:C41)=1 -> TRUE
B44: Working Capital
B45: Inventory | C45: % of uts sold
C46: Commercial | D46: 0.08
C47: Residential | D47: 0.15
E48: Turnover Ratio
B49: Receivables for commercial | C49: Days | D49: 45 | E49: =365/D49 -> 8.1111111
...

Sheet Schedules
B3: Start Date | F3: =DATE(YEAR(Assumption!$C$9),4,1) -> 45017 | G3: =F4+1 -> 45383 | H3: =G4+1 -> 45748 | I3: =H4+1 -> 46113 | J3: =I4+1 -> 46478 | K3: =J4+1 -> 46844
B4: End Date | F4: =EDATE(F3,12)-1 -> 45382 | G4: =EDATE(G3,12)-1 -> 45747 | H4: =EDATE(H3,12)-1 -> 46112 | I4: =EDATE(I3,12)-1 -> 46477 | J4: =EDATE(J3,12)-1 -> 46843 | K4: =EDATE(K3,12)-1 -> 47208
B6: Handover Flag | F6: =AND(F4>=Assumption!$C$11,Schedules!F3<=Assumption!$C$11) -> TRUE | G6: =AND(G4>=Assumption!$C$11,Schedules!G3<=Assumption!$C$11) -> FALSE | H6: =AND(H4>=Assumption!$C$11,Schedules!H3<=Assumption!$C$11) -> FALSE | I6: =AND(I4>=Assumption!$C$11,Schedules!I3<=Assumption!$C$11) -> FALSE | J6: =AND(J4>=Assumption!$C$11,Schedules!J3<=Assumption!$C$11) -> FALSE | K6: =AND(K4>=Assumption!$C$11,Schedules!K3<=Assumption!$C$11) -> FALSE
B7: Operation Flag | F7: =F4>=Assumption!$C$11 -> TRUE | G7: =G4>=Assumption!$C$11 -> TRUE | H7: =H4>=Assumption!$C$11 -> TRUE | I7: =I4>=Assumption!$C$11 -> TRUE | J7: =J4>=Assumption!$C$11 -> TRUE | K7: =K4>=Assumption!$C$11 -> TRUE
B8: Number of days in a Year | F8: =F4-F3+1 -> 366 | G8: =G4-G3+1 -> 365 | H8: =H4-H3+1 -> 365 | I8: =I4-I3+1 -> 365 | J8: =J4-J3+1 -> 366 | K8: =K4-K3+1 -> 365
B9: Number of Operating days in a Year | F9: =MIN(F4-Assumption!$C$11+1,Schedules!F8)*Schedules!F7 -> 366 | G9: =MIN(G4-Assumption!$C$11+1,Schedules!G8)*Schedules!G7 -> 365 | H9: =MIN(H4-Assumption!$C$11+1,Schedules!H8)*Schedules!H7 -> 365 | I9: =MIN(I4-Assumption!$C$11+1,Schedules!I8)*Schedules!I7 -> 365 | J9: =MIN(J4-Assumption!$C$11+1,Schedules!J8)*Schedules!J7 -> 366 | K9: =MIN(K4-Assumption!$C$11+1,Schedules!K8)*Schedules!K7 -> 365
B10: Count- Operational Year | F10: =C10+F7 -> 1 | G10: =F10+G7 -> 2 | H10: =G10+H7 -> 3 | I10: =H10+I7 -> 4 | J10: =I10+J7 -> 5 | K10: =J10+K7 -> 6
B12: Revenue Schedule
B13: Commercial Project
B14: No. of panel | F14: =Assumption!D58/Assumption!D65 -> 3184.9315 | G14: =G16/G15 -> 4398.2387 | H14: =H16/H15 -> 6073.7583 | I14: =I16/I15 -> 8387.5709 | J14: =J16/J15 -> 11582.836 | K14: =K16/K15 -> 15995.345
B15: Price of 1 panel | F15: =Assumption!D67 -> 72000 | G15: =(F15*Assumption!$C$29)+F15 -> 75600 | H15: =G15*Assumption!$C$29+G15 -> 79380 | I15: =H15*Assumption!$C$29+H15 -> 83349 | J15: =I15*Assumption!$C$29+I15 -> 87516.45 | K15: =J15*Assumption!$C$29+J15 -> 91892.272
B16: Revenue | F16: =F14*Assumption!D67 -> 2.2931507e+08 | G16: =F16*Assumption!$D$74+F16 -> 3.3250685e+08 | H16: =G16*Assumption!$D$74+G16 -> 4.8213493e+08 | I16: =H16*Assumption!$D$74+H16 -> 6.9909565e+08 | J16: =I16*Assumption!$D$74+I16 -> 1.0136887e+09 | K16: =J16*Assumption!$D$74+J16 -> 1.4698486e+09
B18: Residential Project
B19: Growth in the energy sold | F19: =Assumption!D83*1% -> 52890 | G19: =F19*Assumption!$D$75+F19 -> 84624 | H19: =G19*Assumption!$D$75+G19 -> 135398.4 | I19: =H19*Assumption!$D$75+H19 -> 216637.44 | J19: =I19*Assumption!D76+I19 -> 335788.03 | K19: =J19*Assumption!D77+J19 -> 503682.05
B20: Price of 1 panel | F20: =Assumption!D93 -> 11000 | G20: =F20*Assumption!$C$30+F20 -> 11275 | H20: =G20*Assumption!$C$30+G20 -> 11556.875 | I20: =H20*Assumption!$C$30+H20 -> 11845.797 | J20: =I20*Assumption!$C$30+I20 -> 12141.942 | K20: =J20*Assumption!$C$30+J20 -> 12445.49
B21: Unit of Panels for Residential | F21: =F19/Assumption!$D$87 -> 82.802348 | G21: =G19/Assumption!$D$87 -> 132.48376 | H21: =H19/Assumption!$D$87 -> 211.97401 | I21: =I19/Assumption!$D$87 -> 339.15842 | J21: =J19/Assumption!$D$87 -> 525.69555 | K21: =K19/Assumption!$D$87 -> 788.54332
B22: Revenue | F22: =F21*F20 -> 910825.83 | G22: =G21*G20 -> 1493754.4 | H22: =H21*H20 -> 2449757.2 | I22: =I21*I20 -> 4017601.7 | J22: =J21*J20 -> 6382964.8 | K22: =K21*K20 -> 9813808.3
B24: Total Revenue | F24: =F22+F16 -> 2.3022589e+08 | G24: =G22+G16 -> 3.340006e+08 | H24: =H22+H16 -> 4.8458469e+08 | I24: =I22+I16 -> 7.0311325e+08 | J24: =J22+J16 -> 1.0200717e+09 | K24: =K22+K16 -> 1.4796624e+09
B26: COGS & Inventory Cost
B27: Commercial Project
B28: Units Sold | F28: =Schedules!F14 -> 3184.9315 | G28: =Schedules!G14 -> 4398.2387 | H28: =Schedules!H14 -> 6073.7583 | I28: =Schedules!I14 -> 8387.5709 | J28: =Schedules!J14 -> 11582.836 | K28: =Schedules!K14 -> 15995.345
B29: Inventory | F29: =F28*Assumption!$D$46 -> 254.79452 | G29: =G28*Assumption!$D$46 -> 351.8591 | H29: =H28*Assumption!$D$46 -> 485.90066 | I29: =I28*Assumption!$D$46 -> 671.00568 | J29: =J28*Assumption!$D$46 -> 926.62689 | K29: =K28*Assumption!$D$46 -> 1279.6276
B30: COGS Unit | F30: =F29+F28 -> 3439.726 | G30: =G29+G28 -> 4750.0978 | H30: =H29+H28 -> 6559.6589 | I30: =I29+I28 -> 9058.5766 | J30: =J29+J28 -> 12509.463 | K30: =K29+K28 -> 17274.973
B31: Cost | F31: 38500 | G31: =F31 -> 38500 | H31: =G31 -> 38500 | I31: =H31 -> 38500 | J31: =I31 -> 38500 | K31: =J31 -> 38500
B32: Total Cost | F32: =F31*F30 -> 1.3242945e+08 | G32: =G31*G30 -> 1.8287877e+08 | H32: =H31*H30 -> 2.5254687e+08 | I32: =I31*I30 -> 3.487552e+08 | J32: =J31*J30 -> 4.8161432e+08 | K32: =K31*K30 -> 6.6508645e+08
B33: Inventory Cost | F33: =F29*F31 -> 9809589 | G33: =G29*G31 -> 13546575 | H33: =H29*H31 -> 18707175 | I33: =I29*I31 -> 25833719 | J33: =J29*J31 -> 35675135 | K33: =K29*K31 -> 49265663
B35: Residential Project
B36: Units Sold | F36: =Schedules!F21 -> 82.802348 | G36: =Schedules!G21 -> 132.48376 | H36: =Schedules!H21 -> 211.97401 | I36: =Schedules!I21 -> 339.15842 | J36: =Schedules!J21 -> 525.69555 | K36: =Schedules!K21 -> 788.54332
B37: Inventory | F37: =F36*Assumption!$D$47 -> 12.420352 | G37: =G36*Assumption!$D$47 -> 19.872564 | H37: =H36*Assumption!$D$47 -> 31.796102 | I37: =I36*Assumption!$D$47 -> 50.873763 | J37: =J36*Assumption!$D$47 -> 78.854332 | K37: =K36*Assumption!$D$47 -> 118.2815
B38: COGS Unit | F38: =F36+F37 -> 95.222701 | G38: =G36+G37 -> 152.35632 | H38: =H36+H37 -> 243.77011 | I38: =I36+I37 -> 390.03218 | J38: =J36+J37 -> 604.54988 | K38: =K36+K37 -> 906.82482
B39: Cost | F39: 6050 | G39: =F39 -> 6050 | H39: =G39 -> 6050 | I39: =H39 -> 6050 | J39: =I39 -> 6050 | K39: =J39 -> 6050
B40: Total Cost | F40: =F39*F38 -> 576097.34 | G40: =G39*G38 -> 921755.74 | H40: =H39*H38 -> 1474809.2 | I40: =I39*I38 -> 2359694.7 | J40: =J39*J38 -> 3657526.8 | K40: =K39*K38 -> 5486290.2
B41: Inventory Cost | F41: =F37*F39 -> 75143.131 | G41: =G37*G39 -> 120229.01 | H41: =H37*H39 -> 192366.42 | I41: =I37*I39 -> 307786.27 | J41: =J37*J39 -> 477068.71 | K41: =K37*K39 -> 715603.07
B43: Total Cogs | F43: =F40+F32 -> 1.3300555e+08 | G43: =G40+G32 -> 1.8380052e+08 | H43: =H40+H32 -> 2.5402168e+08 | I43: =I40+I32 -> 3.5111489e+08 | J43: =J40+J32 -> 4.8527185e+08 | K43: =K40+K32 -> 6.7057274e+08
B44: Total Inventory | F44: =F41+F33 -> 9884732.2 | G44: =G41+G33 -> 13666804 | H44: =H41+H33 -> 18899542 | I44: =I41+I33 -> 26141505 | J44: =J41+J33 -> 36152204 | K44: =K41+K33 -> 49981266
B46: COGS Breakup
B47: Material Cost | F47: =Assumption!$C$14*Schedules!F$43 -> 66502775 | G47: =Assumption!$C$14*Schedules!G$43 -> 91900261 | H47: =Assumption!$C$14*Schedules!H$43 -> 1.2701084e+08 | I47: =Assumption!$C$14*Schedules!I$43 -> 1.7555745e+08 | J47: =Assumption!$C$14*Schedules!J$43 -> 2.4263593e+08 | K47: =Assumption!$C$14*Schedules!K$43 -> 3.3528637e+08
B48: Manufacturing cost | F48: =Assumption!$C$15*Schedules!F$43 -> 33251387 | G48: =Assumption!$C$15*Schedules!G$43 -> 45950131 | H48: =Assumption!$C$15*Schedules!H$43 -> 63505420 | I48: =Assumption!$C$15*Schedules!I$43 -> 87778724 | J48: =Assumption!$C$15*Schedules!J$43 -> 1.2131796e+08 | K48: =Assumption!$C$15*Schedules!K$43 -> 1.6764318e+08
B49: R&D | F49: =Assumption!$C$16*Schedules!F$43 -> 2660111 | G49: =Assumption!$C$16*Schedules!G$43 -> 3676010.5 | H49: =Assumption!$C$16*Schedules!H$43 -> 5080433.6 | I49: =Assumption!$C$16*Schedules!I$43 -> 7022297.9 | J49: =Assumption!$C$16*Schedules!J$43 -> 9705437 | K49: =Assumption!$C$16*Schedules!K$43 -> 13411455
B50: Transportation and Logistics | F50: =Assumption!$C$17*Schedules!F$43 -> 30591276 | G50: =Assumption!$C$17*Schedules!G$43 -> 42274120 | H50: =Assumption!$C$17*Schedules!H$43 -> 58424986 | I50: =Assumption!$C$17*Schedules!I$43 -> 80756426 | J50: =Assumption!$C$17*Schedules!J$43 -> 1.1161253e+08 | K50: =Assumption!$C$17*Schedules!K$43 -> 1.5423173e+08
...

Sheet Income Statement
B2: INCOME STATEMENT
D3: 2024 | E3: 2025 | F3: 2026 | G3: 2027 | H3: 2028 | I3: 2029
B5: Revenue | D5: =Schedules!F24 -> 2.3022589e+08 | E5: =Schedules!G24 -> 3.340006e+08 | F5: =Schedules!H24 -> 4.8458469e+08 | G5: =Schedules!I24 -> 7.0311325e+08 | H5: =Schedules!J24 -> 1.0200717e+09 | I5: =Schedules!K24 -> 1.4796624e+09
B6: Less: COGS | D6: =Schedules!F40+Schedules!F43 -> 1.3358165e+08 | E6: =Schedules!G40+Schedules!G43 -> 1.8472228e+08 | F6: =Schedules!H40+Schedules!H43 -> 2.5549649e+08 | G6: =Schedules!I40+Schedules!I43 -> 3.5347459e+08 | H6: =Schedules!J40+Schedules!J43 -> 4.8892938e+08 | I6: =Schedules!K40+Schedules!K43 -> 6.7605903e+08
B7: Gross Profit | D7: =D5-D6 -> 96644248 | E7: =E5-E6 -> 1.4927833e+08 | F7: =F5-F6 -> 2.290882e+08 | G7: =G5-G6 -> 3.4963866e+08 | H7: =H5-H6 -> 5.3114228e+08 | I7: =I5-I6 -> 8.0360339e+08
B9: Less: Operating Expenses | D9: =Schedules!F57 -> 98997135 | E9: =Schedules!G57 -> 1.4362026e+08 | F9: =Schedules!H57 -> 2.0837142e+08 | G9: =Schedules!I57 -> 3.023387e+08 | H9: =Schedules!J57 -> 4.3863081e+08 | I9: =Schedules!K57 -> 6.3625484e+08
B10: EBITDA | D10: =D7-D9 -> -2352887 | E10: =E7-E9 -> 5658065.5 | F10: =F7-F9 -> 20716785 | G10: =G7-G9 -> 47299965 | H10: =H7-H9 -> 92511468 | I10: =I7-I9 -> 1.6734855e+08
B12: Less: Depreciation and Amortization | D12: =Schedules!F94 -> 5608000 | E12: =Schedules!G94 -> 5608000 | F12: =Schedules!H94 -> 5608000 | G12: =Schedules!I94 -> 5608000 | H12: =Schedules!J94 -> 5608000 | I12: =Schedules!K94 -> 5608000
B13: EBIT | D13: =D10-D12 -> -7960887 | E13: =E10-E12 -> 50065.49 | F13: =F10-F12 -> 15108785 | G13: =G10-G12 -> 41691965 | H13: =H10-H12 -> 86903468 | I13: =I10-I12 -> 1.6174055e+08
B15: Less: Interest Expenses | D15: ='Balance Sheet'!D17*'Income Statement'!$C$15 -> 0 | E15: =Schedules!G147 -> 469625 | F15: =Schedules!H147 -> 414375 | G15: =Schedules!I147 -> 359125 | H15: =Schedules!J147 -> 303875 | I15: =Schedules!K147 -> 248625
B16: EBT | D16: =D13-D15 -> -7960887 | E16: =E13-E15 -> -419559.51 | F16: =F13-F15 -> 14694410 | G16: =G13-G15 -> 41332840 | H16: =H13-H15 -> 86599593 | I16: =I13-I15 -> 1.6149192e+08
B17: Less: Tax | D17: =D16*Schedules!F153 -> 0 | E17: =E16*Schedules!G153 -> 0 | F17: =F16*Schedules!H153 -> 3673602.6 | G17: =G16*Schedules!I153 -> 10333210 | H17: =H16*Schedules!J153 -> 21649898 | I17: =I16*Schedules!K153 -> 40372981
B19: Net Profit | D19: =D16-IF(D17<0,0,D17) -> -7960887 | E19: =E16-IF(E17<0,0,E17) -> -419559.51 | F19: =F16-IF(F17<0,0,F17) -> 11020808 | G19: =G16-IF(G17<0,0,G17) -> 30999630 | H19: =H16-IF(H17<0,0,H17) -> 64949695 | I19: =I16-IF(I17<0,0,I17) -> 1.2111894e+08
B21: Transfer to Reserve and Surplus | D21: =D19+C21 -> -7960887 | E21: =E19+D21 -> -8380446.5 | F21: =F19+E21 -> 2640361.2 | G21: =G19+F21 -> 33639991 | H21: =H19+G21 -> 98589686 | I21: =I19+H21 -> 2.1970863e+08

Sheet Balance Sheet
B2: BALANCE SHEET
D3: 2024 | E3: 2025 | F3: 2026 | G3: 2027 | H3: 2028 | I3: 2029
B5: Non Current Assets
B6: Net Fixed Assets | D6: =Schedules!F101 -> 91392000 | E6: =Schedules!G101 -> 216784000 | F6: =Schedules!H101 -> 365176000 | G6: =Schedules!I101 -> 525568000 | H6: =Schedules!J101 -> 687960000 | I6: =Schedules!K101 -> 852352000
B7: Capital WIP | D7: =Schedules!F82 -> 0 | E7: =Schedules!G82 -> 0 | F7: =Schedules!H82 -> 0 | G7: =Schedules!I82 -> 0 | H7: =Schedules!J82 -> 0 | I7: =Schedules!K82 -> 0
B9: Current Assets
B10: Cash | D10: ='Cash Flow Statement'!D26 -> -8533693.2 | E10: ='Cash Flow Statement'!E26 -> -66161448 | F10: ='Cash Flow Statement'!F26 -> -2.1072936e+08 | G10: ='Cash Flow Statement'!G26 -> -3.5099659e+08 | H10: ='Cash Flow Statement'!H26 -> -4.6497685e+08 | I10: ='Cash Flow Statement'!I26 -> -5.3344928e+08
B11: Inventory | D11: =Schedules!F62 -> 9884732.2 | E11: =Schedules!G62 -> 13666804 | F11: =Schedules!H62 -> 18899542 | G11: =Schedules!I62 -> 26141505 | H11: =Schedules!J62 -> 36152204 | I11: =Schedules!K62 -> 49981266
B12: Accounts Receivables | D12: =Schedules!F61 -> 28384014 | E12: =Schedules!G61 -> 41178157 | F12: =Schedules!H61 -> 59743318 | G12: =Schedules!I61 -> 86685196 | H12: =Schedules!J61 -> 1.2576226e+08 | I12: =Schedules!K61 -> 1.8242413e+08
B14: Total Assets | D14: =SUM(D10:D12,D6:D7) -> 1.2112705e+08 | E14: =SUM(E10:E12,E6:E7) -> 2.0546751e+08 | F14: =SUM(F10:F12,F6:F7) -> 2.330895e+08 | G14: =SUM(G10:G12,G6:G7) -> 2.8739811e+08 | H14: =SUM(H10:H12,H6:H7) -> 3.8489761e+08 | I14: =SUM(I10:I12,I6:I7) -> 5.5130811e+08
B16: Non Current Liabilities
B17: Long terms Debts | D17: =Schedules!F144 -> 7650000 | E17: =Schedules!G144 -> 6800000 | F17: =Schedules!H144 -> 5950000 | G17: =Schedules!I144 -> 5100000 | H17: =Schedules!J144 -> 4250000 | I17: =Schedules!K144 -> 3400000
B18: Government Grant | D18: =Schedules!F134 -> 0 | E18: =Schedules!G134 -> 25500000 | F18: =Schedules!H134 -> 25500000 | G18: =Schedules!I134 -> 25500000 | H18: =Schedules!J134 -> 25500000 | I18: =Schedules!K134 -> 25500000
B20: Current Liabilities
B21: Accounts Payables | D21: =Schedules!F65 -> 32937940 | E21: =Schedules!G65 -> 45547959 | F21: =Schedules!H65 -> 62999134 | G21: =Schedules!I65 -> 87158118 | H21: =Schedules!J65 -> 1.2055793e+08 | I21: =Schedules!K65 -> 1.6669949e+08
B23: Shareholder's Funds
B24: Shareholders equity | D24: =Schedules!F128 -> 88500000 | E24: =Schedules!G128 -> 136000000 | F24: =Schedules!H128 -> 136000000 | G24: =Schedules!I128 -> 136000000 | H24: =Schedules!J128 -> 136000000 | I24: =Schedules!K128 -> 136000000
B25: Reserves and Surplus | D25: ='Income Statement'!D21 -> -7960887 | E25: ='Income Statement'!E21 -> -8380446.5 | F25: ='Income Statement'!F21 -> 2640361.2 | G25: ='Income Statement'!G21 -> 33639991 | H25: ='Income Statement'!H21 -> 98589686 | I25: ='Income Statement'!I21 -> 2.1970863e+08
B27: Total Equity and Liabilities | D27: =SUM(D17:D25) -> 1.2112705e+08 | E27: =SUM(E17:E25) -> 2.0546751e+08 | F27: =SUM(F17:F25) -> 2.330895e+08 | G27: =SUM(G17:G25) -> 2.8739811e+08 | H27: =SUM(H17:H25) -> 3.8489761e+08 | I27: =SUM(I17:I25) -> 5.5130811e+08
D29: =D27=D14 -> TRUE | E29: =E27=E14 -> TRUE | F29: =F27=F14 -> TRUE | G29: =G27=G14 -> TRUE | H29: =H27=H14 -> TRUE | I29: =I27=I14 -> TRUE

Sheet Cash Flow Statement
B2: CASHFLOW STATEMENT
D3: 2024 | E3: 2025 | F3: 2026 | G3: 2027 | H3: 2028 | I3: 2029
B5: Net Income | D5: ='Income Statement'!D19 -> -7960887 | E5: ='Income Statement'!E19 -> -419559.51 | F5: ='Income Statement'!F19 -> 11020808 | G5: ='Income Statement'!G19 -> 30999630 | H5: ='Income Statement'!H19 -> 64949695 | I5: ='Income Statement'!I19 -> 1.2111894e+08
B6: Finance Cost | D6: =Schedules!F147 -> 248625 | E6: =Schedules!G147 -> 469625 | F6: =Schedules!H147 -> 414375 | G6: =Schedules!I147 -> 359125 | H6: =Schedules!J147 -> 303875 | I6: =Schedules!K147 -> 248625
B7: Depreciation & Amortization | D7: ='Income Statement'!D12 -> 5608000 | E7: ='Income Statement'!E12 -> 5608000 | F7: ='Income Statement'!F12 -> 5608000 | G7: ='Income Statement'!G12 -> 5608000 | H7: ='Income Statement'!H12 -> 5608000 | I7: ='Income Statement'!I12 -> 5608000
B8: Changes in Working Capital | D8: =Schedules!F69 -> -5330806.3 | E8: =Schedules!G69 -> -3966195.6 | F8: =Schedules!H69 -> -6346724 | G8: =Schedules!I69 -> -10024857 | H8: =Schedules!J69 -> -15687952 | I8: =Schedules!K69 -> -24349378
B9: Other Operating Cash Flows | D9: 0 | E9: 0 | F9: 0 | G9: 0 | H9: 0 | I9: 0
B10: Cash Flow from Operations | D10: =SUM(D5:D9) -> -7435068.2 | E10: =SUM(E5:E9) -> 1691869.9 | F10: =SUM(F5:F9) -> 10696459 | G10: =SUM(G5:G9) -> 26941898 | H10: =SUM(H5:H9) -> 55173618 | I10: =SUM(I5:I9) -> 1.0262619e+08
B12: Capital Expenditure | D12: =-Schedules!F76 -> -97000000 | E12: =-Schedules!G76 -> -131000000 | F12: =-Schedules!H76 -> -154000000 | G12: =-Schedules!I76 -> -166000000 | H12: =-Schedules!J76 -> -168000000 | I12: =-Schedules!K76 -> -170000000
B13: Cash Flow from Investing | D13: =SUM(D12:D12) -> -97000000 | E13: =SUM(E12:E12) -> -131000000 | F13: =SUM(F12:F12) -> -154000000 | G13: =SUM(G12:G12) -> -166000000 | H13: =SUM(H12:H12) -> -168000000 | I13: =SUM(I12:I12) -> -170000000
B15: Equity Issuance / Equity Raise | D15: =Schedules!F126 -> 88500000 | E15: =Schedules!G126 -> 47500000 | F15: =Schedules!H126 -> 0 | G15: =Schedules!I126 -> 0 | H15: =Schedules!J126 -> 0 | I15: =Schedules!K126 -> 0
B16: Equity Repurchase | D16: 0 | E16: 0 | F16: 0 | G16: 0 | H16: 0 | I16: 0
B17: LT Debt Issuance | D17: =Schedules!F142 -> 8500000 | E17: =Schedules!G142 -> 0 | F17: =Schedules!H142 -> 0 | G17: =Schedules!I142 -> 0 | H17: =Schedules!J142 -> 0 | I17: =Schedules!K142 -> 0
B18: LT Debt Repayment | D18: =-Schedules!F143 -> -850000 | E18: =-Schedules!G143 -> -850000 | F18: =-Schedules!H143 -> -850000 | G18: =-Schedules!I143 -> -850000 | H18: =-Schedules!J143 -> -850000 | I18: =-Schedules!K143 -> -850000
B19: Government Grant | D19: =Schedules!F132 -> 0 | E19: =Schedules!G132 -> 25500000 | F19: =Schedules!H132 -> 0 | G19: =Schedules!I132 -> 0 | H19: =Schedules!J132 -> 0 | I19: =Schedules!K132 -> 0
B20: Interest on Debt Paid | D20: =-Schedules!F147 -> -248625 | E20: =-Schedules!G147 -> -469625 | F20: =-Schedules!H147 -> -414375 | G20: =-Schedules!I147 -> -359125 | H20: =-Schedules!J147 -> -303875 | I20: =-Schedules!K147 -> -248625
B21: Cash Flow from Financing | D21: =SUM(D15:D20) -> 95901375 | E21: =SUM(E15:E20) -> 71680375 | F21: =SUM(F15:F20) -> -1264375 | G21: =SUM(G15:G20) -> -1209125 | H21: =SUM(H15:H20) -> -1153875 | I21: =SUM(I15:I20) -> -1098625
B23: Changes in Cash and Cash Equivalents | D23: =SUM(D10,D13,D21) -> -8533693.2 | E23: =SUM(E10,E13,E21) -> -57627755 | F23: =SUM(F10,F13,F21) -> -1.4456792e+08 | G23: =SUM(G10,G13,G21) -> -1.4026723e+08 | H23: =SUM(H10,H13,H21) -> -1.1398026e+08 | I23: =SUM(I10,I13,I21) -> -68472436
B24: Add: Opening Cash Balance | D24: =C26 -> 0 | E24: =D26 -> -8533693.2 | F24: =E26 -> -66161448 | G24: =F26 -> -2.1072936e+08 | H24: =G26 -> -3.5099659e+08 | I24: =H26 -> -4.6497685e+08
B26: Ending Cash Balance | D26: =D24+D23 -> -8533693.2 | E26: =E24+E23 -> -66161448 | F26: =F24+F23 -> -2.1072936e+08 | G26: =G24+G23 -> -3.5099659e+08 | H26: =H24+H23 -> -4.6497685e+08 | I26: =I24+I23 -> -5.3344928e+08

Sheet Output Analysis-NPV_IRR
B1: ANALYSIS
D2: 2024 | E2: 2025 | F2: 2026 | G2: 2027 | H2: 2028 | I2: 2029
A4: # | B4: IRR
B6: NOPAT | D6: ='Income Statement'!D13-'Income Statement'!D17 -> -7960887 | E6: ='Income Statement'!E13-'Income Statement'!E17 -> 50065.49 | F6: ='Income Statement'!F13-'Income Statement'!F17 -> 11435183 | G6: ='Income Statement'!G13-'Income Statement'!G17 -> 31358755 | H6: ='Income Statement'!H13-'Income Statement'!H17 -> 65253570 | I6: ='Income Statement'!I13-'Income Statement'!I17 -> 1.2136757e+08
B7: Depreciation | D7: ='Income Statement'!D12 -> 5608000 | E7: ='Income Statement'!E12 -> 5608000 | F7: ='Income Statement'!F12 -> 5608000 | G7: ='Income Statement'!G12 -> 5608000 | H7: ='Income Statement'!H12 -> 5608000 | I7: ='Income Statement'!I12 -> 5608000
B8: Changes in WC | D8: =Schedules!F69 -> -5330806.3 | E8: =Schedules!G69 -> -3966195.6 | F8: =Schedules!H69 -> -6346724 | G8: =Schedules!I69 -> -10024857 | H8: =Schedules!J69 -> -15687952 | I8: =Schedules!K69 -> -24349378
B9: Changes in FC Req | D9: =Schedules!F76-Schedules!E76 -> 97000000 | E9: =Schedules!G76-Schedules!F76 -> 34000000 | F9: =Schedules!H76-Schedules!G76 -> 23000000 | G9: =Schedules!I76-Schedules!H76 -> 12000000 | H9: =Schedules!J76-Schedules!I76 -> 2000000 | I9: =Schedules!K76-Schedules!J76 -> 2000000
B11: FCFF | D11: =D6+D7+D8-D9 -> -1.0468369e+08 | E11: =E6+E7+E8-E9 -> -32308130 | F11: =F6+F7+F8-F9 -> -12303541 | G11: =G6+G7+G8-G9 -> 14941898 | H11: =H6+H7+H8-H9 -> 53173618 | I11: =I6+I7+I8-I9 -> 1.0062619e+08
B13: IRR | D13: =IRR(D11:I11) -> 0.030120005
A17: # | B17: NPV
B19: Debt rate | C19: =Schedules!E146 -> 0.065
B20: Tax rate | C20: =Schedules!C152 -> 0.25
A21: 0.05 | B21: After-tax cost of debt | C21: =C19*(1-C20) -> 0.04875 | E21: Market Risk Premium Calculation | H21: Risk Free Rate Calculation
E22: Year | F22: Returns of Nifty(Annual) | H22: Bond Rate on Govt of India Bond-10 year | J22: 0.06867
B23: Market premium | C23: =F28-J24 -> 0.08124 | E23: 2023 | F23: 0.1941 | H23: Bond Rate on Govt of India Bond-5 year | J23: 0.06789
B24: Beta | C24: 0.6 | E24: 2022 | F24: 0.0432 | H24: Average Rf Rate | J24: 0.0683
B25: Risk Free Rate | C25: =J24 -> 0.0683 | E25: 2021 | F25: 0.2412
A26: 0.8 | B26: Cost of Equity (CAPM) | C26: =C25+(C24*C23) -> 0.117044 | E26: 2020 | F26: 0.149
A27: 0.15 | B27: Cost of government grant | C27: 0 | E27: 2019 | F27: 0.1202
B28: WACC | C28: =A21*C21+A26*C26+A27*C27 -> 0.0960727 | F28: =AVERAGE(F23:F27) -> 0.14954
B30: NPV | C30: =NPV(C28,D11:I11) -> -29746212

Sheet References
B1: Our assumptions are based on the following news
A3: #
A11: #
A22: #
A31: #
A37: #
A44: #
